Workbook

Sheet 吉布斯自由能汇总
A1: TiFe | I1: TiMn | Q1: TiHf | X1: TiRe | AF1: TiNb | AM1: TiMo | AT1: TiV | BA1: TiZr | BH1: TiCo | BO1: TiTi | BV1: TiW | CC1: TiTa | CK1: TiCr | CR1: 单核Ti | CY1: TiNi
A2: H2O2+C6H12 | I2: H2O2+C6H12 | Q2: + | X2: H2O2+C6H12 | AF2: H2O2+C6H12 | AM2: H2O2+C6H12 | AT2: H2O2+C6H12 | BA2: H2O2+C6H12 | BH2: H2O2+C6H12 | BO2: H2O2+C6H12 | BV2: H2O2+C6H12 | CC2: H2O2+C6H12 | CK2: H2O2+C6H12 | CR2: H2O2+C6H12 | CY2: H2O2+C6H12
A3: eV | B3: E0 | C3: T | D3: 地址 | E3: ΔG | F3: G | I3: eV | J3: E0 | K3: T | L3: 地址 | M3: ΔG | N3: G | Q3: eV | R3: E0 | S3: T | T3: 地址 | U3: ΔG | V3: G | X3: eV | Y3: E0 | Z3: T | AA3: 地址 | AB3: ΔG | AC3: G | AF3: eV | AG3: E0 | AH3: T | AI3: 地址 | AJ3: ΔG | AK3: G | AM3: eV | AN3: E0 | AO3: T | AP3: 地址 | AQ3: ΔG | AR3: G | AT3: eV | AU3: E0 | AV3: T | AW3: 地址 | AX3: ΔG | AY3: G | BA3: eV | BB3: E0 | BC3: T | BD3: 地址 | BE3: ΔG | BF3: G | BH3: eV | BI3: E0 | BJ3: T | BK3: 地址 | BL3: ΔG | BM3: G | BO3: eV | BP3: E0 | BQ3: T | BR3: 地址 | BS3: ΔG | BT3: G | BV3: eV | BW3: E0 | BX3: T | BY3: 地址 | BZ3: ΔG | CA3: G | CC3: eV | CD3: E0 | CE3: T | CG3: 地址 | CH3: ΔG | CI3: G | CK3: eV | CL3: E0 | CM3: T | CN3: 地址 | CO3: ΔG | CP3: G | CR3: eV | CS3: E0 | CT3: T | CU3: 地址 | CV3: ΔG | CW3: G | CY3: eV | CZ3: E0 | DA3: T | DB3: 地址 | DC3: ΔG | DD3: G
A4: 1 | B4: -870.07124 | C4: 333.15 | D4: /home/liyaqian/node01data/ts-1/mfi/si66o98h68/test5/tife/tiofe-t/freq | E4: 0.173983 | F4: =B4+E4 -> -869.89726 | I4: 1 | J4: -872.09367 | K4: 333.15 | L4: /home/zhengxiuhui/node02data/lyq/ts-1/timn/tiomn-t | M4: 0.176331 | N4: =J4+M4 -> -871.91734 | Q4: 1 | R4: -878.57421 | S4: 333.15 | T4: /home/liyaqian/node01data/ts-1/mfi/tihf/freq | U4: 0.13539 | V4: =R4+U4 -> -878.43882 | X4: 1 | Y4: -873.49551 | Z4: 333.15 | AA4: /home/xiuhui/lyq/ts-1/tire/tiore-t/freq | AB4: 0.114715 | AC4: =Y4+AB4 -> -873.3808 | AF4: 1 | AG4: -876.10024 | AH4: 333.15 | AI4: /home/liyaqian/node01data/ts-1/mfi/tinb/tionb-t/freq | AJ4: 0.310647 | AK4: =AG4+AJ4 -> -875.78959 | AM4: 1 | AN4: -874.0544 | AO4: 333.15 | AP4: /home/zhengxiuhui/node03data/lyq/ts-1/timo/tiomo-t/freq | AQ4: 0.133879 | AR4: =AN4+AQ4 -> -873.92052 | AT4: 1 | AU4: -875.08097 | AV4: 333.15 | AW4: /home/xiuhui/lyq/ts-1/tiv/tiov-t/freq | AX4: 0.180418 | AY4: =AU4+AX4 -> -874.90055 | BA4: 1 | BB4: -876.80766 | BC4: 333.15 | BD4: /home/liyaqian/node01data/ts-1/mfi/tizr/tiozr-t/freq | BE4: 0.159331 | BF4: =BB4+BE4 -> -876.64833 | BH4: 1 | BI4: -867.78173 | BJ4: 333.15 | BK4: /home/zhengxiuhui/node02data/lyq/ts-1/tico/tico-t/freq | BL4: 0.143233 | BM4: =BI4+BL4 -> -867.6385 | BO4: 1 | BP4: -874.10182 | BQ4: 333.15 | BR4: /home/xiuhui/lyq/ts-1/titi/1titi/freq | BS4: 0.237742 | BT4: =BP4+BS4 -> -873.86408 | BV4: 1 | BW4: -876.3624 | BX4: 333.15 | BY4: /home/zhengxiuhui/node02data/lyq/ts-1/tiw/tiow-t/freq | BZ4: 0.122321 | CA4: =BW4+BZ4 -> -876.24008 | CC4: 1 | CD4: -877.8318 | CE4: 333.15 | CF4: /home/zhengxiuhui/node03data/lyq/ts-1/tita/tita-t/t1/freq | CG4: /home/liyaqian/node01data/ts-1/mfi/tita/tita-t/freq | CH4: 0.257263 | CI4: =CD4+CH4 -> -877.57454 | CK4: 1 | CL4: -872.48801 | CM4: 333.15 | CN4: /home/xiuhui/lyq/ts-1/ticr/1ticr/freq | CO4: 0.214109 | CP4: =CL4+CO4 -> -872.2739 | CR4: 1 | CS4: -873.8619 | CT4: 333.15 | CU4: /home/liyaqian/node01data/ts-1/mfi/ti/1/freq | CV4: 0.231262 | CW4: =CS4+CV4 -> -873.63064 | CY4: 1 | CZ4: -863.44497 | DA4: 333.15 | DB4: /home/liyaqian/node01data/ts-1/mfi/tini/tioni-t/freq | DC4: 0.19059 | DD4: =CZ4+DC4 -> -863.25438
A5: 总 | C5: 333.15 | F5: =F4+F57+F58 -> -983.05057 | G5: -983.05057 | I5: 总 | K5: 333.15 | N5: =N4+F57+F58 -> -985.07065 | Q5: 总 | S5: 333.15 | V5: =V4+F57+F58 -> -991.59214 | X5: 总 | Z5: 333.15 | AC5: =AC4+F57+F58 -> -986.53411 | AF5: 总 | AH5: 333.15 | AK5: =AK4+F57+F58 -> -988.94291 | AM5: 总 | AO5: 333.15 | AR5: =AR4+F57+F58 -> -987.07383 | AT5: 总 | AV5: 333.15 | AY5: =AY4+F57+F58 -> -988.05386 | BA5: 总 | BC5: 333.15 | BF5: =BF4+F58+F57 -> -989.80165 | BH5: 总 | BJ5: 333.15 | BM5: =BM4+F57+F58 -> -980.79181 | BO5: 总 | BQ5: 333.15 | BT5: =BT4+F57+F58 -> -987.01739 | BV5: 总 | BX5: 333.15 | CA5: =CA4+F57+F58 -> -989.39339 | CC5: 总 | CE5: 333.15 | CI5: =CI4+F58+F57 -> -990.72785 | CK5: 总 | CM5: 333.15 | CP5: =CP4+F57+F58 -> -985.42721 | CR5: 总 | CT5: 333.15 | CW5: =CW4+F57+F58 -> -986.78395 | CY5: 总 | DA5: 333.15 | DD5: =DD4+F57+F58 -> -976.40769
A6: H2O2*+C6H12 | G6: -983.26894 | I6: H2O2*+C6H12 | O6: -985.07065 | Q6: H2O2*+C6H12 | X6: H2O2*+C6H12 | AF6: H2O2*+C6H12 | AM6: H2O2*+C6H12 | AT6: H2O2*+C6H12 | BA6: H2O2*+C6H12 | BH6: H2O2*+C6H12 | BO6: H2O2*+C6H12 | BV6: H2O2*+C6H12 | CC6: H2O2*+C6H12 | CK6: H2O2*+C6H12 | CR6: H2O2*+C6H12 | CY6: H2O2*+C6H12
B7: E0 | C7: T | D7: 地址 | E7: ΔG | F7: G | G7: -984.51929 | J7: E0 | K7: T | L7: 地址 | M7: ΔG | N7: G | O7: -985.2968 | R7: E0 | S7: T | T7: 地址 | U7: ΔG | V7: G | Y7: E0 | Z7: T | AA7: 地址 | AB7: ΔG | AC7: G | AD7: -986.53411 | AG7: E0 | AH7: T | AI7: 地址 | AJ7: ΔG | AK7: G | AL7: -988.94291 | AN7: E0 | AO7: T | AP7: 地址 | AQ7: ΔG | AR7: G | AU7: E0 | AV7: T | AW7: 地址 | AX7: ΔG | AY7: G | AZ7: -988.05386 | BB7: E0 | BC7: T | BD7: 地址 | BE7: ΔG | BF7: G | BI7: E0 | BJ7: T | BK7: 地址 | BL7: ΔG | BM7: G | BP7: E0 | BQ7: T | BR7: 地址 | BS7: ΔG | BT7: G | BW7: E0 | BX7: T | BY7: 地址 | BZ7: ΔG | CA7: G | CD7: E0 | CE7: T | CG7: 地址 | CH7: ΔG | CI7: G | CL7: E0 | CM7: T | CN7: 地址 | CO7: ΔG | CP7: G | CS7: E0 | CT7: T | CU7: 地址 | CV7: ΔG | CW7: G | CZ7: E0 | DA7: T | DB7: 地址 | DC7: ΔG | DD7: G
A8: 2 | B8: -889.02827 | C8: 333.15 | D8: /home/liyaqian/node01data/ts-1/mfi/si66o98h68/h2o2-ts/mo/freq | E8: 0.790555 | F8: =B8+E8 -> -888.23771 | G8: -984.35987 | I8: 2 | J8: -891.0626 | K8: 333.15 | L8: /home/zhengxiuhui/node02data/lyq/ts-1/timn/2h+ooh/freq | M8: 0.797032 | N8: =J8+M8 -> -890.26557 | O8: -985.22924 | Q8: 2 | R8: -897.21298 | S8: 333.15 | T8: /home/liyaqian/node01data/ts-1/mfi/tihf/2h+oh/freq | U8: 0.792624 | V8: =R8+U8 -> -896.42035 | X8: 2 | Y8: -891.90948 | Z8: 333.15 | AA8: /home/xiuhui/lyq/ts-1/tire/2o+ooh/freq | AC8: =Y8+AB8 -> -891.90948 | AD8: -986.9407 | AF8: 2 | AG8: -894.78714 | AH8: 333.15 | AI8: /home/liyaqian/node01data/ts-1/mfi/tinb/2o+oh/freq | AJ8: 0.797975 | AK8: =AG8+AJ8 -> -893.98917 | AL8: -989.02039 | AM8: 2 | AN8: -892.66988 | AO8: 333.15 | AP8: /home/zhengxiuhui/node03data/lyq/ts-1/timo/2h+ooh/freq | AQ8: 0.751815 | AR8: =AN8+AQ8 -> -891.91806 | AT8: 2 | AU8: -893.36602 | AV8: 333.15 | AW8: /home/xiuhui/lyq/ts-1/tiv/2h+ooh/freq | AX8: 0.847134 | AY8: =AU8+AX8 -> -892.51888 | AZ8: -987.55011 | BA8: 2 | BB8: -895.42248 | BC8: 333.15 | BD8: /home/liyaqian/node01data/ts-1/mfi/tizr/2o+ooh/freq | BE8: 0.816213 | BF8: =BB8+BE8 -> -894.60627 | BH8: 2 | BI8: -886.3643 | BJ8: 333.15 | BK8: /home/zhengxiuhui/lyq/ts-1/tico/2h+ooh/freq | BL8: 0.810765 | BM8: =BI8+BL8 -> -885.55353 | BO8: 2 | BP8: -893.0304 | BQ8: 333.15 | BR8: /home/xiuhui/lyq/ts-1/titi/2ooh+h/freq | BS8: 0.898331 | BT8: =BP8+BS8 -> -892.13207 | BV8: 2 | BW8: -894.82669 | BX8: 333.15 | BY8: /home/zhengxiuhui/node02data/lyq/ts-1/tiw/2o+ooh/freq | BZ8: 0.754667 | CA8: =BW8+BZ8 -> -894.07202 | CC8: 2 | CD8: -896.72842 | CE8: 333.15 | CG8: /home/zhengxiuhui/node03data/lyq/ts-1/tita/2h+ooh/freq | CH8: 0.777564 | CI8: =CD8+CH8 -> -895.95086 | CJ8: -990.72785 | CK8: 2 | CL8: -891.20786 | CM8: 333.15 | CN8: /home/xiuhui/lyq/ts-1/ticr/2ooh+h/freq | CO8: 0.85451 | CP8: =CL8+CO8 -> -890.35335 | CQ8: -985.42721 | CR8: 2 | CS8: -892.02756 | CT8: 333.15 | CU8: /home/liyaqian/node01data/ts-1/mfi/ti/2ooh+h/freq | CV8: 0.914665 | CW8: =CS8+CV8 -> -891.1129 | CY8: 2 | CZ8: -883.02753 | DA8: 333.15 | DB8: /home/liyaqian/node01data/ts-1/mfi/tini/2ooh+h/freq | DC8: 0.869174 | DD8: =CZ8+DC8 -> -882.15836
A9: 总 | C9: 333.15 | F9: =F8+F58 -> -983.26894 | G9: -986.69827 | I9: 总 | K9: 333.15 | N9: =N8+F58 -> -985.2968 | O9: -984.89494 | Q9: 总 | S9: 333.15 | V9: =V8+F58 -> -991.45158 | X9: 总 | Z9: 333.15 | AA9: /home/liyaqian/node01data/ts-1/mfi/tire/ts/freq | AC9: =AC8+F58 -> -986.9407 | AD9: -986.72668 | AF9: 总 | AH9: 333.15 | AK9: =AK8+F58 -> -989.02039 | AL9: -991.24382 | AM9: 总 | AO9: 333.15 | AR9: =AR8+F58 -> -986.94928 | AT9: 总 | AV9: 333.15 | AY9: =AY8+F58 -> -987.55011 | AZ9: -987.61498 | BA9: 总 | BC9: 333.15 | BF9: =BF8+F58 -> -989.63749 | BH9: 总 | BJ9: 333.15 | BM9: =BM8+F58 -> -980.58475 | BO9: 总 | BQ9: 333.15 | BT9: =BT8+F58 -> -987.16329 | BU9: -987.01739 | BV9: 总 | BX9: 333.15 | CA9: =CA8+F58 -> -989.10324 | CB9: -989.39339 | CC9: 总 | CE9: 333.15 | CI9: =CI8+F58 -> -990.98208 | CJ9: -990.98208 | CK9: 总 | CM9: 333.15 | CP9: =CP8+F58 -> -985.38457 | CQ9: -985.38457 | CR9: 总 | CT9: 333.15 | CW9: =CW8+F58 -> -986.14412 | CY9: 总 | DA9: 333.15 | DD9: =DD8+F58 -> -977.18958
A10: (H2O2)(C6H12)* | G10: -986.23688 | I10: (H2O2)(C6H12)* | O10: -987.38021 | Q10: (H2O2)(C6H12)* | X10: (H2O2)(C6H12)* | AD10: -986.28184 | AF10: (H2O2)(C6H12)* | AL10: -990.11587 | AM10: (H2O2)(C6H12)* | AT10: (H2O2)(C6H12)* | AZ10: -987.45784 | BA10: (H2O2)(C6H12)* | BH10: (H2O2)(C6H12)* | BO10: (H2O2)(C6H12)* | BU10: -987.16329 | BV10: (H2O2)(C6H12)* | CB10: -989.10324 | CC10: (H2O2)(C6H12)* | CJ10: -990.92629 | CK10: (H2O2)(C6H12)* | CQ10: -985.38003 | CR10: (H2O2)(C6H12)* | CX10: -986.78395 | CY10: (H2O2)(C6H12)*
B11: E0 | C11: T | D11: 地址 | E11: ΔG | F11: G | G11: -986.20278 | J11: E0 | K11: T | L11: 地址 | M11: ΔG | N11: G | O11: -987.0457 | R11: E0 | S11: T | T11: 地址 | U11: ΔG | V11: G | Y11: E0 | Z11: T | AA11: 地址 | AB11: ΔG | AC11: G | AD11: -988.65412 | AG11: E0 | AH11: T | AI11: 地址 | AJ11: ΔG | AK11: G | AL11: -991.37534 | AN11: E0 | AO11: T | AP11: 地址 | AQ11: ΔG | AR11: G | AU11: E0 | AV11: T | AW11: 地址 | AX11: ΔG | AY11: G | AZ11: -989.80258 | BB11: E0 | BC11: T | BD11: 地址 | BE11: ΔG | BF11: G | BI11: E0 | BJ11: T | BK11: 地址 | BL11: ΔG | BM11: G | BP11: E0 | BQ11: T | BR11: 地址 | BS11: ΔG | BT11: G | BU11: -987.15551 | BW11: E0 | BX11: T | BY11: 地址 | BZ11: ΔG | CA11: G | CB11: -989.00034 | CD11: E0 | CE11: T | CG11: 地址 | CH11: ΔG | CI11: G | CJ11: -992.10093 | CL11: E0 | CM11: T | CN11: 地址 | CO11: ΔG | CP11: G | CQ11: -989.27575 | CS11: E0 | CT11: T | CU11: 地址 | CV11: ΔG | CW11: G | CX11: -986.14412 | CZ11: E0 | DA11: T | DB11: 地址 | DC11: ΔG | DD11: G
A12: 3 | B12: -989.49361 | C12: 333.15 | D12: /home/liyaqian/node01data/ts-1/mfi/si66o98h68/1-hex+ooh+h/chu3/freq | E12: 4.974321 | F12: =B12+E12 -> -984.51929 | I12: 3 | J12: -990.11643 | K12: 333.15 | L12: /home/zhengxiuhui/node02data/lyq/ts-1/timn/3/chu/freq | M12: 4.887182 | N12: =J12+M12 -> -985.22924 | O12: -987.15982 | Q12: 3 | R12: -996.2369 | S12: 333.15 | T12: /home/liyaqian/node01data/ts-1/mfi/tihf/3/chu/freq | U12: 4.830437 | V12: =R12+U12 -> -991.40646 | X12: 3 | Y12: -991.52236 | Z12: 333.15 | AA12: /home/liyaqian/node01data/ts-1/mfi/tire/chu2/freq | AB12: 4.795677 | AC12: =Y12+AB12 -> -986.72668 | AD12: -988.2163 | AF12: 3 | AG12: -993.85987 | AI12: /home/liyaqian/node01data/ts-1/mfi/tinb/3/chu11/freq | AJ12: =9.702894/2 -> 4.851447 | AK12: =AG12+AJ12 -> -989.00843 | AL12: -990.9982 | AM12: 3 | AN12: -991.71938 | AO12: 333.15 | AP12: /home/zhengxiuhui/node03data/lyq/ts-1/timo/3/chu2/freq | AQ12: 4.797307 | AR12: =AN12+AQ12 -> -986.92207 | AT12: 3 | AU12: -992.44037 | AV12: 333.15 | AW12: /home/xiuhui/lyq/ts-1/tiv/3/chu2/freq | AX12: 4.825389 | AY12: =AU12+AX12 -> -987.61498 | AZ12: -989.43898 | BA12: 3 | BB12: -994.46339 | BC12: 333.15 | BD12: /home/liyaqian/node01data/ts-1/mfi/tizr/3/chu2/freq | BE12: 4.848189 | BF12: =BB12+BE12 -> -989.6152 | BH12: 3 | BI12: -986.97852 | BJ12: 333.15 | BK12: /home/zhengxiuhui/node02data/lyq/ts-1/tico/3/chu2/freq | BL12: 4.781938 | BM12: =BI12+BL12 -> -982.19659 | BO12: 3 | BP12: -992.09265 | BQ12: 333.15 | BR12: /home/xiuhui/lyq/ts-1/titi/3/chu/freq | BS12: 4.937146 | BT12: =BP12+BS12 -> -987.15551 | BU12: -986.86089 | BV12: 3 | BW12: -993.8796 | BX12: 333.15 | BY12: /home/zhengxiuhui/node02data/lyq/ts-1/tiw/3/chu/freq | BZ12: 4.879254 | CA12: =BW12+BZ12 -> -989.00034 | CB12: -989.56699 | CC12: 3 | CD12: -995.75527 | CE12: 333.15 | CG12: /home/zhengxiuhui/node03data/lyq/ts-1/tita/3/chu/freq | CH12: 4.828978 | CI12: =CD12+CH12 -> -990.92629 | CJ12: -993.37883 | CK12: 3 | CL12: -990.26527 | CM12: 333.15 | CN12: /home/xiuhui/lyq/ts-1/ticr/3/chu/freq | CO12: 4.885241 | CP12: =CL12+CO12 -> -985.38003 | CQ12: -987.63789 | CR12: 3 | CS12: -991.17154 | CT12: 333.15 | CU12: /home/liyaqian/node01data/ts-1/mfi/ti/3/chu/freq | CV12: 4.935816 | CW12: =CS12+CV12 -> -986.23573 | CX12: -986.23573 | CY12: 3 | CZ12: -982.18279 | DA12: 333.15 | DB12: /home/liyaqian/node01data/ts-1/mfi/tini/3/chu/freq | DC12: 4.898002 | DD12: =CZ12+DC12 -> -977.28479
A13: 总 | C13: 333.15 | F13: -984.51929 | I13: 总 | K13: 333.15 | N13: =N12 -> -985.22924 | Q13: 总 | S13: 333.15 | V13: =V12 -> -991.40646 | X13: 总 | Z13: 333.15 | AC13: =AC12 -> -986.72668 | AD13: -988.62372 | AF13: 总 | AH13: 333.15 | AK13: =AK12 -> -989.00843 | AL13: -991.18708 | AM13: 总 | AO13: 333.15 | AR13: =AR12 -> -986.92207 | AT13: 总 | AV13: 333.15 | AY13: =AY12 -> -987.61498 | AZ13: -990.14257 | BA13: 总 | BC13: 333.15 | BF13: =BF12 -> -989.6152 | BH13: 总 | BJ13: 333.15 | BM13: =BM12 -> -982.19659 | BO13: 总 | BQ13: 333.15 | BT13: =BT12 -> -987.15551 | BU13: -989.5672 | BV13: 总 | BX13: 333.15 | CA13: =CA12 -> -989.00034 | CB13: -991.67613 | CC13: 总 | CE13: 333.15 | CI13: =CI12 -> -990.92629 | CJ13: -993.01289 | CK13: 总 | CM13: 333.15 | CP13: =CP12 -> -985.38003 | CQ13: -987.30644 | CR13: 总 | CT13: 333.15 | CW13: =CW12 -> -986.23573 | CX13: -986.04216 | CY13: 总 | DA13: 333.15 | DD13: =DD12 -> -977.28479
A14: ts | I14: ts | Q14: ts | X14: ts | AF14: ts | AM14: ts | AT14: ts | BA14: ts | BH14: ts | BO14: ts | BU14: -989.6899 | BV14: ts | CB14: -991.24599 | CC14: ts | CJ14: -992.9454 | CK14: ts | CQ14: -987.51607 | CR14: ts | CX14: -988.67142 | CY14: ts
B15: E0 | C15: T | D15: 地址 | E15: ΔG | F15: G | G15: =F17-F13 -> 0.159416 | J15: E0 | K15: T | L15: 地址 | M15: ΔG | N15: G | O15: =N17-N13 -> 0.3343 | R15: E0 | S15: T | T15: 地址 | U15: ΔG | V15: G | Y15: E0 | Z15: T | AA15: 地址 | AB15: ΔG | AC15: G | AG15: E0 | AH15: T | AI15: 地址 | AJ15: ΔG | AK15: G | AN15: E0 | AO15: T | AP15: 地址 | AQ15: ΔG | AR15: G | AU15: E0 | AV15: T | AW15: 地址 | AX15: ΔG | AY15: G | BB15: E0 | BC15: T | BD15: 地址 | BE15: ΔG | BF15: G | BI15: E0 | BJ15: T | BK15: 地址 | BL15: ΔG | BM15: G | BP15: E0 | BQ15: T | BR15: 地址 | BS15: ΔG | BT15: G | BU15: -989.87295 | BW15: E0 | BX15: T | BY15: 地址 | BZ15: ΔG | CA15: G | CB15: -991.48221 | CD15: E0 | CE15: T | CG15: 地址 | CH15: ΔG | CI15: G | CL15: E0 | CM15: T | CN15: 地址 | CO15: ΔG | CP15: G | CS15: E0 | CT15: T | CU15: 地址 | CV15: ΔG | CW15: G | CX15: -988.17398 | CZ15: E0 | DA15: T | DB15: 地址 | DC15: ΔG | DD15: G
A16: 4 | B16: -989.1862 | C16: 333.15 | D16: /home/liyaqian/node01data/ts-1/mfi/si66o98h68tife/ts-feq | E16: 4.826326 | F16: =B16+E16 -> -984.35987 | I16: 4 | J16: -989.79031 | K16: 333.15 | L16: /home/zhengxiuhui/node02data/lyq/ts-1/timn/3/neb1-1/02/39-idm/424-opt/freq | M16: 4.895366 | N16: =J16+M16 -> -984.89494 | Q16: 4 | R16: -996.01926 | S16: 333.15 | T16: /home/liyaqian/node01data/ts-1/mfi/tihf/3/neb1-1/02/50-idm/290-opt//freq | U16: 4.844638 | V16: =R16+U16 -> -991.17462 | W16: =V16-V12 -> 0.231842 | X16: 4 | Y16: -990.9633 | Z16: 333.15 | AA16: /home/liyaqian/node01data/ts-1/mfi/tire/neb2-1/02/freq | AB16: 4.681462 | AC16: =Y16+AB16 -> -986.28184 | AD16: =AC16-AC12 -> 0.444846 | AF16: 4 | AG16: -994.95226 | AH16: 333.15 | AI16: /home/liyaqian/node01data/ts-1/mfi/tinb/3/neb1-1/02/ts-1/78-opt/freq | AJ16: 4.836388 | AK16: =AG16+AJ16 -> -990.11587 | AL16: =AK17-AK13 -> -1.107446 | AM16: 4 | AN16: -991.54319 | AO16: 333.15 | AP16: /home/zhengxiuhui/node03data/lyq/ts-1/timo/3/neb1-1/02/ts-1/40-opt/freq | AQ16: 4.759305 | AR16: =AN16+AQ16 -> -986.78389 | AT16: 4 | AU16: -992.26678 | AV16: 333.15 | AW16: /home/xiuhui/lyq/ts-1/tiv/3/neb1-1/02/27-idm/49-opt/freq | AX16: 4.808949 | AY16: =AU16+AX16 -> -987.45784 | BA16: 4 | BB16: -994.19263 | BC16: 333.15 | BD16: /home/liyaqian/node01data/ts-1/mfi/tizr/3/neb1-1/02/9-idm/413-opt/freq | BE16: 4.854842 | BF16: =BB16+BE16 -> -989.33779 | BG16: =BF16-BF12 -> 0.277407 | BH16: 4 | BI16: -986.57935 | BJ16: 333.15 | BK16: /home/vasp/li/ts-1/tico/freq3 | BL16: 4.939107 | BM16: =BI16+BL16 -> -981.64024 | BN16: =BM16-BM12 -> 0.556344 | BO16: 4 | BP16: -991.79001 | BQ16: 333.15 | BR16: /home/xiuhui/lyq/ts-1/titi/3/neb1-1/02/15-idm/277-opt/freq | BS16: 4.929118 | BT16: =BP16+BS16 -> -986.86089 | BV16: 4 | BW16: -994.305 | BX16: 333.15 | BY16: /home/zhengxiuhui/node02data/lyq/ts-1/tiw/3/neb1-1/03/03-0opt/448-opt/freq | BZ16: 4.738006 | CA16: =BW16+BZ16 -> -989.56699 | CC16: 4 | CD16: -996.93102 | CE16: 333.15 | CG16: /home/zhengxiuhui/node03data/lyq/ts-1/tita/3/neb1-1/02/54-idm/132-opt/freq | CH16: 4.830091 | CI16: =CD16+CH16 -> -992.10093 | CK16: 4 | CL16: -989.9347 | CM16: 333.15 | CN16: /home/zhengxiuhui/node02data/lyq/ts-1/ticr/neb1-1/01/69-idm/296-opt/freq2/259-opt/freq | CO16: 5.075068 | CP16: =CL16+CO16 -> -984.85963 | CR16: 4 | CS16: -990.98549 | CT16: 333.15 | CU16: /home/liyaqian/node01data/ts-1/mfi/ti/3/neb1-1/02/66-idm/358-opt/freq | CV16: 4.943327 | CW16: =CS16+CV16 -> -986.04216 | CX16: -988.8731 | CY16: 4 | CZ16: -981.68711 | DA16: 333.15 | DB16: /home/zhengxiuhui/node03data/lyq/ts-1/tini/3/12-idm/345-opt/freq | DC16: 4.919487 | DD16: =CZ16+DC16 -> -976.76762 | DE16: =DD17-DD13 -> 0.51717
A17: 总 | C17: 333.15 | F17: -984.35987 | I17: 总 | K17: 333.15 | N17: =N16 -> -984.89494 | Q17: 总 | S17: 333.15 | V17: =V16 -> -991.17462 | X17: 总 | Z17: 333.15 | AC17: =AC16 -> -986.28184 | AF17: 总 | AH17: 333.15 | AK17: =AK16 -> -990.11587 | AM17: 总 | AO17: 333.15 | AR17: =AR16 -> -986.78389 | AS17: =AR16-AR12 -> 0.138184 | AT17: 总 | AV17: 333.15 | AY17: =AY16 -> -987.45784 | AZ17: =AY16-AY12 -> 0.157149 | BA17: 总 | BC17: 333.15 | BF17: =BF16 -> -989.33779 | BH17: 总 | BJ17: 333.15 | BK17: 99节点 | BM17: =BM16 -> -981.64024 | BO17: 总 | BQ17: 333.15 | BT17: =BT16 -> -986.86089 | BV17: 总 | BX17: 333.15 | CA17: =CA16 -> -989.56699 | CC17: 总 | CE17: 333.15 | CI17: =CI16 -> -992.10093 | CK17: 总 | CM17: 333.15 | CP17: =CP16 -> -984.85963 | CQ17: =CP17-CP13 -> 0.520405 | CR17: 总 | CT17: 333.15 | CW17: =CW16 -> -986.04216 | CY17: 总 | DA17: 333.15 | DD17: =DD16 -> -976.76762
A18: (C6H12O)(H2O)* | I18: (C6H12O)(H2O)* | Q18: (C6H12O)(H2O)* | X18: (C6H12O)(H2O)* | AF18: (C6H12O)(H2O)* | AM18: (C6H12O)(H2O)* | AT18: (C6H12O)(H2O)* | BA18: (C6H12O)(H2O)* | BH18: (C6H12O)(H2O)* | BO18: (C6H12O)(H2O)* | BV18: (C6H12O)(H2O)* | CC18: (C6H12O)(H2O)* | CK18: (C6H12O)(H2O)* | CR18: (C6H12O)(H2O)* | CX18: =CW16-CW12 -> 0.193563 | CY18: (C6H12O)(H2O)*
B19: E0 | C19: T | D19: 地址 | E19: ΔG | F19: G | J19: E0 | K19: T | L19: 地址 | M19: ΔG | N19: G | R19: E0 | S19: T | T19: 地址 | U19: ΔG | V19: G | Y19: E0 | Z19: T | AA19: 地址 | AB19: ΔG | AC19: G | AG19: E0 | AH19: T | AI19: 地址 | AJ19: ΔG | AK19: G | AN19: E0 | AO19: T | AP19: 地址 | AQ19: ΔG | AR19: G | AU19: E0 | AV19: T | AW19: 地址 | AX19: ΔG | AY19: G | BB19: E0 | BC19: T | BD19: 地址 | BE19: ΔG | BF19: G | BI19: E0 | BJ19: T | BK19: 地址 | BL19: ΔG | BM19: G | BP19: E0 | BQ19: T | BR19: 地址 | BS19: ΔG | BT19: G | BW19: E0 | BX19: T | BY19: 地址 | BZ19: ΔG | CA19: G | CD19: E0 | CE19: T | CG19: 地址 | CH19: ΔG | CI19: G | CL19: E0 | CM19: T | CN19: 地址 | CO19: ΔG | CP19: G | CS19: E0 | CT19: T | CU19: 地址 | CV19: ΔG | CW19: G | CZ19: E0 | DA19: T | DB19: 地址 | DC19: ΔG | DD19: G
A20: 5 | B20: -991.70269 | C20: 333.15 | D20: /home/liyaqian/node01data/ts-1/mfi/si66o98h68/1-hex+ooh+h/mo4/freq | E20: 5.00442 | F20: =B20+E20 -> -986.69827 | I20: 5 | J20: -992.38729 | K20: 333.15 | L20: /home/zhengxiuhui/node02data/lyq/ts-1/timn/3/mo/freq | M20: 5.007082 | N20: =J20+M20 -> -987.38021 | Q20: 5 | R20: -998.75082 | S20: 333.15 | T20: /home/liyaqian/node01data/ts-1/mfi/tihf/3/mo/freq | U20: 4.932595 | V20: =R20+U20 -> -993.81822 | X20: 5 | Y20: -993.57173 | Z20: 333.15 | AA20: /home/xiuhui/lyq/ts-1/tire/3/mo/freq | AB20: 4.917615 | AC20: =Y20+AB20 -> -988.65412 | AF20: 5 | AG20: -996.32794 | AH20: 333.15 | AI20: /home/liyaqian/node01data/ts-1/mfi/tinb/3/mo/freq | AJ20: 4.952597 | AK20: =AG20+AJ20 -> -991.37534 | AM20: 6 | AN20: -888.51606 | AO20: 333.15 | AP20: /home/zhengxiuhui/node03data/lyq/ts-1/timo/6o+oh/freq | AQ20: 0.683373 | AR20: =AN20+AQ20 -> -887.83269 | AT20: 5 | AU20: -994.81057 | AV20: 333.15 | AW20: /home/xiuhui/lyq/ts-1/tiv/3/mo/freq | AX20: 5.007989 | AY20: =AU20+AX20 -> -989.80258 | BA20: 5 | BB20: -996.93021 | BC20: 333.15 | BD20: /home/liyaqian/node01data/ts-1/mfi/tizr/3/mo/freq | BE20: 4.962992 | BF20: =BB20+BE20 -> -991.96722 | BH20: 5 | BI20: -987.43997 | BJ20: 333.15 | BK20: /home/zhengxiuhui/node02data/lyq/ts-1/tico/3/mo2/freq | BL20: 5.003698 | BM20: =BI20+BL20 -> -982.43627 | BO20: 5 | BP20: -994.63488 | BQ20: 333.15 | BR20: /home/xiuhui/lyq/ts-1/titi/3/mo/freq | BS20: 5.067686 | BT20: =BP20+BS20 -> -989.5672 | BV20: 5 | BW20: -996.61986 | BX20: 333.15 | BY20: /home/zhengxiuhui/node02data/lyq/ts-1/tiw/3/mo/freq | BZ20: 4.943734 | CA20: =BW20+BZ20 -> -991.67613 | CC20: 5 | CD20: -998.31803 | CE20: 333.15 | CG20: /home/zhengxiuhui/node03data/lyq/ts-1/tita/3/mo/freq | CH20: 4.939201 | CI20: =CD20+CH20 -> -993.37883 | CK20: 5 | CL20: -992.69094 | CM20: 333.15 | CN20: /home/xiuhui/lyq/ts-1/ticr/3/mo/freq | CO20: 5.053049 | CP20: =CL20+CO20 -> -987.63789 | CR20: 5 | CS20: -993.75508 | CT20: 333.15 | CU20: /home/liyaqian/node01data/ts-1/mfi/ti/3/mo/freq | CV20: 5.083655 | CW20: =CS20+CV20 -> -988.67142 | CY20: 5 | CZ20: -984.23781 | DA20: 333.15 | DB20: /home/liyaqian/node01data/ts-1/mfi/tini/3/mo | DC20: 5.0318 | DD20: =CZ20+DC20 -> -979.20601
A21: 总 | C21: 333.15 | F21: -986.69827 | I21: 总 | K21: 333.15 | N21: =N20 -> -987.38021 | Q21: 总 | S21: 333.15 | V21: =V20 -> -993.81822 | X21: 总 | Z21: 333.15 | AC21: =AC20 -> -988.65412 | AF21: 总 | AH21: 333.15 | AK21: =AK20 -> -991.37534 | AM21: 总 | AO21: 333.15 | AR21: =AR20+F60 -> -988.87046 | AT21: 总 | AV21: 333.15 | AY21: =AY20 -> -989.80258 | BA21: 总 | BC21: 333.15 | BF21: =BF20 -> -991.96722 | BH21: 总 | BJ21: 333.15 | BM21: =BM20 -> -982.43627 | BO21: 总 | BQ21: 333.15 | BT21: =BT20 -> -989.5672 | BV21: 总 | BX21: 333.15 | CA21: =CA20 -> -991.67613 | CC21: 总 | CE21: 333.15 | CI21: =CI20 -> -993.37883 | CK21: 总 | CM21: 333.15 | CP21: =CP20 -> -987.63789 | CR21: 总 | CT21: 333.15 | CW21: =CW20 -> -988.67142 | CY21: 总 | DA21: 333.15 | DD21: =DD20 -> -979.20601
A22: H_b*+O*+H_a* | I22: H_b*+O*+H_a* | Q22: H_b*+O*+H_a* | X22: H_b*+O*+H_a* | AF22: H_b*+O*+H_a* | AM22: H_b*+O*+H_a* | AT22: H_b*+O*+H_a* | BA22: H_b*+O*+H_a* | BH22: H_b*+O*+H_a* | BO22: H_b*+O*+H_a* | BV22: H_b*+O*+H_a* | CC22: H_b*+O*+H_a* | CK22: H_b*+O*+H_a* | CR22: H_b*+O*+H_a* | CY22: H_b*+O*+H_a*
B23: E0 | C23: T | D23: 地址 | E23: ΔG | F23: G | J23: E0 | K23: T | L23: 地址 | M23: ΔG | N23: G | R23: E0 | S23: T | T23: 地址 | U23: ΔG | V23: G | Y23: E0 | Z23: T | AA23: 地址 | AB23: ΔG | AC23: G | AG23: E0 | AH23: T | AI23: 地址 | AJ23: ΔG | AK23: G | AN23: E0 | AO23: T | AP23: 地址 | AQ23: ΔG | AR23: G | AU23: E0 | AV23: T | AW23: 地址 | AX23: ΔG | AY23: G | BB23: E0 | BC23: T | BD23: 地址 | BE23: ΔG | BF23: G | BI23: E0 | BJ23: T | BK23: 地址 | BL23: ΔG | BM23: G | BP23: E0 | BQ23: T | BR23: 地址 | BS23: ΔG | BT23: G | BW23: E0 | BX23: T | BY23: 地址 | BZ23: ΔG | CA23: G | CD23: E0 | CE23: T | CG23: 地址 | CH23: ΔG | CI23: G | CL23: E0 | CM23: T | CN23: 地址 | CO23: ΔG | CP23: G | CS23: E0 | CT23: T | CU23: 地址 | CV23: ΔG | CW23: G | CZ23: E0 | DA23: T | DB23: 地址 | DC23: ΔG | DD23: G
A24: 6 | B24: -885.3163 | D24: /home/liyaqian/node01data/ts-1/mfi/si66o98h68/1-hex+ooh+h/6h2o-ts/chu3/freq | E24: =1.46853/2 -> 0.734265 | F24: =B24+E24 -> -884.58204 | I24: 6 | J24: -885.47737 | L24: /home/zhengxiuhui/node02data/lyq/ts-1/timn/h2o/chu/freq | M24: =1.530536/2 -> 0.765268 | N24: =J24+M24 -> -884.71211 | Q24: 6 | R24: -890.87086 | T24: /home/liyaqian/node01data/ts-1/mfi/tihf/h2o/freq | U24: =1.475906/2 -> 0.737953 | V24: =R24+U24 -> -890.13291 | X24: 6 | Y24: -887.08374 | AA24: /home/xiuhui/lyq/ts-1/tire/h2o/chu | AB24: =1.436096/2 -> 0.718048 | AC24: =Y24+AB24 -> -886.36569 | AF24: 6 | AG24: -888.90225 | AI24: /home/liyaqian/node01data/ts-1/mfi/tinb/h2o/chu/freq | AJ24: =1.466934/2 -> 0.733467 | AK24: =AG24+AJ24 -> -888.16878 | AM24: 7 | AN24: -887.08374 | AP24: /home/zhengxiuhui/node02data/lyq/ts-1/timo/h2o/chu/freq | AQ24: =1.462976/2 -> 0.731488 | AR24: =AN24+AQ24 -> -886.35225 | AU24: -887.68915 | AW24: /home/xiuhui/lyq/ts-1/tiv/h2o/chu/freq | AX24: =1.546541/2 -> 0.7732705 | AY24: =AU24+AX24 -> -886.91588 | BA24: 6 | BB24: -894.16288 | BD24: /home/liyaqian/node01data/ts-1/mfi/tizr/h2o/chu3/freq | BE24: =1.443179/2 -> 0.7215895 | BF24: =BB24+BE24 -> -893.44129 | BI24: -881.34502 | BK24: /home/zhengxiuhui/node02data/lyq/ts-1/tico/h2o/chu/freq | BL24: =1.515518/2 -> 0.757759 | BM24: =BI24+BL24 -> -880.58726 | BP24: -888.10153 | BR24: /home/xiuhui/lyq/ts-1/titi/h2o/chu | BS24: =1.766909/2 -> 0.8834545 | BT24: =BP24+BS24 -> -887.21807 | BV24: 6 | BW24: -889.53933 | BY24: /home/zhengxiuhui/node02data/lyq/ts-1/tiw/h2o/chu2/freq | BZ24: =1.46839/2 -> 0.734195 | CA24: =BW24+BZ24 -> -888.80514 | CD24: -890.66953 | CG24: /home/zhengxiuhui/node02data/lyq/ts-1/tita/h2o/chu/freq | CH24: =1.413682/2 -> 0.706841 | CI24: =CD24+CH24 -> -889.96269 | CL24: -885.602 | CN24: /home/zhengxiuhui/node02data/lyq/ts-1/ticr/h2o/neb1-1/neb0-3_new/01/freq | CO24: =1.544361/2 -> 0.7721805 | CP24: =CL24+CO24 -> -884.82982 | CS24: -888.38988 | CU24: /home/liyaqian/node01data/ts-1/mfi/ti/h2o/chu4/freq | CV24: =1.696545/2 -> 0.8482725 | CW24: =CS24+CV24 -> -887.5416 | CZ24: -877.99653 | DB24: /home/zhengxiuhui/node02data/lyq/ts-1/tini/h2o/chu/freq | DC24: =1.569884/2 -> 0.784942 | DD24: =CZ24+DC24 -> -877.21159
A25: 总 | I25: 总 | Q25: 总 | X25: 总 | AF25: 总 | AM25: 总 | BA25: 总 | BV25: 总
A26: ts | I26: ts | Q26: ts | X26: ts | AF26: ts | AM26: ts | AT26: ts | BA26: ts | BH26: ts | BO26: ts | BV26: ts | CC26: ts | CK26: ts | CR26: ts | CY26: ts
B27: E0 | C27: T | D27: 地址 | E27: ΔG | F27: G | J27: E0 | K27: T | L27: 地址 | M27: ΔG | N27: G | R27: E0 | S27: T | T27: 地址 | U27: ΔG | V27: G | Y27: E0 | Z27: T | AA27: 地址 | AB27: ΔG | AC27: G | AG27: E0 | AH27: T | AI27: 地址 | AJ27: ΔG | AK27: G | AN27: E0 | AO27: T | AP27: 地址 | AQ27: ΔG | AR27: G | AU27: E0 | AV27: T | AW27: 地址 | AX27: ΔG | AY27: G | BB27: E0 | BC27: T | BD27: 地址 | BE27: ΔG | BF27: G | BI27: E0 | BJ27: T | BK27: 地址 | BL27: ΔG | BM27: G | BP27: E0 | BQ27: T | BR27: 地址 | BS27: ΔG | BT27: G | BW27: E0 | BX27: T | BY27: 地址 | BZ27: ΔG | CA27: G | CD27: E0 | CE27: T | CG27: 地址 | CH27: ΔG | CI27: G | CL27: E0 | CM27: T | CN27: 地址 | CO27: ΔG | CP27: G | CS27: E0 | CT27: T | CU27: 地址 | CV27: ΔG | CW27: G | CZ27: E0 | DA27: T | DB27: 地址 | DC27: ΔG | DD27: G
A28: 7 | B28: -885.1446 | D28: /home/liyaqian/node01data/ts-1/mfi/si66o98h68/1-hex+ooh+h/6h2o-ts/neb3-2/01/freq | E28: =1.471085/2 -> 0.7355425 | F28: =B28+E28 -> -884.40906 | G28: =F28-F24 -> 0.1729815 | I28: 7 | J28: -885.18825 | L28: /home/zhengxiuhui/node03data/lyq/ts-1/timn/6/01-7 | M28: =1.331707/2 -> 0.6658535 | N28: =J28+M28 -> -884.52239 | O28: =N28-N24 -> 0.1897145 | Q28: 7 | R28: -890.5265 | T28: /home/liyaqian/node01data/ts-1/mfi/tihf/h2o/neb1-1/01/34-opt/1374-opt/freq | U28: =1.235118 /2 -> 0.617559 | V28: =R28+U28 -> -889.90895 | W28: =V28-V24 -> 0.223965 | X28: 7 | Y28: -886.74821 | AA28: /home/xiuhui/lyq/ts-1/tire/h2o/neb1-1_1/52-opt/1506-opt/freq | AB28: =1.20078/2 -> 0.60039 | AC28: =Y28+AB28 -> -886.14782 | AD28: =AC28-AC24 -> 0.217873 | AF28: 7 | AG28: -888.7985 | AI28: /home/liyaqian/node01data/ts-1/mfi/tinb/h2o/neb1-1/01/freq | AJ28: =1.314189/2 -> 0.6570945 | AK28: =AG28+AJ28 -> -888.14141 | AL28: =AK28-AK24 -> 0.0273745 | AM28: 8 | AN28: -886.9531 | AP28: /home/zhengxiuhui/node03data/lyq/ts-1/timo/h2o/neb1-1/01/01-4freq/1581-opt/freq | AQ28: =1.176066/2 -> 0.588033 | AR28: =AN28+AQ28 -> -886.36507 | AS28: =AR28-AR24 -> -0.01282 | AU28: -887.6327 | AW28: /home/xiuhui/lyq/ts-1/tiv/h2o/neb1-1/01/freq | AX28: =1.384279 /2 -> 0.6921395 | AY28: =AU28+AX28 -> -886.94056 | AZ28: =AY28-AY24 -> -0.024677 | BB28: -894.0887 | BD28: /home/liyaqian/node01data/ts-1/mfi/tizr/h2o/neb3-4/01/freq | BE28: =1.417183/2 -> 0.7085915 | BF28: =BB28+BE28 -> -893.38011 | BG28: =BF28-BF24 -> 0.061183 | BI28: -881.00875 | BK28: /home/zhengxiuhui/node02data/lyq/ts-1/tico/h2o/neb1-1/01/01-5/1073-opt/freq | BL28: =1.294954/2 -> 0.647477 | BM28: =BI28+BL28 -> -880.36127 | BN28: =BM28-BM24 -> 0.225994 | BP28: -887.9818 | BR28: /home/xiuhui/lyq/ts-1/titi/h2o/neb1-1/01 | BS28: =1.839825/2 -> 0.9199125 | BT28: =BP28+BS28 -> -887.06189 | BV28: 7 | BW28: -889.3072 | BY28: /home/zhengxiuhui/node03data/lyq/ts-1/tiw/h2o/neb2-1/01/freq | BZ28: =1.220604/2 -> 0.610302 | CA28: =BW28+BZ28 -> -888.6969 | CD28: -890.5731 | CG28: /home/zhengxiuhui/node02data/lyq/ts-1/tita/h2o/neb1-1/01/freq | CH28: =1.25275/2 -> 0.626375 | CI28: =CD28+CH28 -> -889.94672 | CL28: -885.53373 | CN28: /home/zhengxiuhui/node02data/lyq/ts-1/ticr/h2o/ts-lasp/1140-opt/freq | CO28: =1.02152/2 -> 0.51076 | CP28: =CL28+CO28 -> -885.02297 | CS28: -888.01391 | CU28: /home/liyaqian/node01data/ts-1/mfi/ti/h2o/ts2-lasp/835-opt/freq | CV28: =1.498747/2 -> 0.7493735 | CW28: =CS28+CV28 -> -887.26453 | CX28: =CW28-CW24 -> 0.277071 | CZ28: -877.86649 | DB28: /home/zhengxiuhui/node02data/lyq/ts-1/tini/h2o/neb1-1/01/23-opt/842-opt/freq | DC28: =1.376013/2 -> 0.6880065 | DD28: =CZ28+DC28 -> -877.17848 | DE28: =DD28-DD24 -> 0.0331075
A29: 总 | I29: 总 | Q29: 总 | X29: 总 | AF29: 总 | AM29: 总 | BV29: 总
A30: OH*+H_a* | I30: OH*+H_a* | Q30: OH*+H_a* | X30: OH*+H_a* | AF30: OH*+H_a* | AM30: OH*+H_a* | AT30: OH*+H_a* | BA30: OH*+H_a* | BH30: OH*+H_a* | BO30: OH*+H_a* | BV30: OH*+H_a* | CC30: OH*+H_a* | CK30: OH*+H_a* | CR30: OH*+H_a* | CY30: OH*+H_a*
B31: E0 | C31: T | D31: 地址 | E31: ΔG | F31: G | I31: 8 | J31: E0 | K31: T | L31: 地址 | M31: ΔG | N31: G | R31: E0 | S31: T | T31: 地址 | U31: ΔG | V31: G | Y31: E0 | Z31: T | AA31: 地址 | AB31: ΔG | AC31: G | AG31: E0 | AH31: T | AI31: 地址 | AJ31: ΔG | AK31: G | AN31: E0 | AO31: T | AP31: 地址 | AQ31: ΔG | AR31: G | AU31: E0 | AV31: T | AW31: 地址 | AX31: ΔG | AY31: G | BB31: E0 | BC31: T | BD31: 地址 | BE31: ΔG | BF31: G | BI31: E0 | BJ31: T | BK31: 地址 | BL31: ΔG | BM31: G | BP31: E0 | BQ31: T | BR31: 地址 | BS31: ΔG | BT31: G | BW31: E0 | BX31: T | BY31: 地址 | BZ31: ΔG | CA31: G | CD31: E0 | CE31: T | CG31: 地址 | CH31: ΔG | CI31: G | CL31: E0 | CM31: T | CN31: 地址 | CO31: ΔG | CP31: G | CS31: E0 | CT31: T | CU31: 地址 | CV31: ΔG | CW31: G | CZ31: E0 | DA31: T | DB31: 地址 | DC31: ΔG | DD31: G
A32: 8 | B32: -885.97597 | C32: 333.15 | D32: /home/liyaqian/node01data/ts-1/mfi/si66o98h68/1-hex+ooh+h/6o+oh_2/freq | E32: 0.776864 | F32: =B32+E32 -> -885.1991 | I32: 总 | J32: -886.79863 | K32: 333.15 | L32: /home/zhengxiuhui/node02data/lyq/ts-1/timn/6h+oh/freq | M32: 0.790707 | N32: =J32+M32 -> -886.00793 | Q32: 8 | R32: -893.14997 | S32: 333.15 | T32: /home/liyaqian/node01data/ts-1/mfi/tihf/6h+oh/freq | U32: 0.751578 | V32: =R32+U32 -> -892.39839 | X32: 8 | Y32: -887.87527 | Z32: 333.15 | AA32: /home/xiuhui/lyq/ts-1/tire/6oh+h/freq | AB32: 0.696748 | AC32: =Y32+AB32 -> -887.17853 | AF32: 8 | AG32: -890.7083 | AH32: 333.15 | AI32: /home/liyaqian/node01data/ts-1/mfi/tinb/6h+oh/freq | AJ32: 0.74787 | AK32: =AG32+AJ32 -> -889.96043 | AM32: 9 | AN32: -994.08416 | AO32: 333.15 | AP32: /home/zhengxiuhui/node03data/lyq/ts-1/timo/3/mo/freq | AQ32: 4.919197 | AR32: =AN32+AQ32 -> -989.16496 | AT32: 6 | AU32: -889.20001 | AV32: 333.15 | AW32: /home/xiuhui/lyq/ts-1/tiv/6o+oh/freq | AX32: 0.798792 | AY32: =AU32+AX32 -> -888.40121 | BA32: 6 | BB32: -891.33496 | BC32: 333.15 | BD32: /home/liyaqian/node01data/ts-1/mfi/tizr/6o+oh/freq | BE32: 0.774789 | BF32: =BB32+BE32 -> -890.56017 | BH32: 6 | BI32: -881.82232 | BJ32: 333.15 | BK32: /home/zhengxiuhui/node02data/lyq/ts-1/tico/6h+oh/freq | BL32: 0.754472 | BM32: =BI32+BL32 -> -881.06784 | BO32: 6 | BP32: -889.68934 | BQ32: 333.15 | BR32: /home/xiuhui/lyq/ts-1/titi/6oh+h/freq | BS32: 1.037214 | BT32: =BP32+BS32 -> -888.65213 | BV32: 8 | BW32: -890.92098 | BX32: 333.15 | BY32: /home/zhengxiuhui/node02data/lyq/ts-1/tiw/6h+oh/freq | BZ32: 0.712754 | CA32: =BW32+BZ32 -> -890.20822 | CC32: 6 | CD32: -892.69817 | CE32: 333.15 | CG32: /home/zhengxiuhui/node03data/lyq/ts-1/tita/6oh+h/freq | CH32: 0.723057 | CI32: =CD32+CH32 -> -891.97511 | CK32: 6 | CL32: -887.09025 | CM32: 333.15 | CN32: /home/zhengxiuhui/node02data/lyq/ts-1/ticr/6oh+h/freq | CO32: 0.821578 | CP32: =CL32+CO32 -> -886.26867 | CS32: -888.01294 | CT32: 333.15 | CU32: /home/liyaqian/node01data/ts-1/mfi/ti/6/freq | CV32: 0.87673 | CW32: =CS32+CV32 -> -887.13621 | CY32: 6 | CZ32: -878.62263 | DA32: 333.15 | DB32: /home/zhengxiuhui/node03data/lyq/ts-1/tini/6oh+h/freq | DC32: 0.836637 | DD32: =CZ32+DC32 -> -877.786
A33: 总 | C33: 333.15 | F33: =F32+F60 -> -986.23688 | K33: 333.15 | N33: =N32+F60 -> -987.0457 | Q33: 总 | S33: 333.15 | V33: =V32+F60 -> -993.43616 | X33: 总 | Z33: 333.15 | AC33: =AC32+F60 -> -988.2163 | AF33: 总 | AH33: 333.15 | AK33: =AK32+F60 -> -990.9982 | AM33: 总 | AO33: 333.15 | AR33: =AR32 -> -989.16496 | AT33: 总 | AV33: 333.15 | AY33: =AY32+F60 -> -989.43898 | BA33: 总 | BC33: 333.15 | BF33: =BF32+F60 -> -991.59794 | BH33: 总 | BJ33: 333.15 | BM33: =BM32+F60 -> -982.10562 | BO33: 总 | BQ33: 333.15 | BT33: =BT32+F60 -> -989.6899 | BV33: 总 | BX33: 333.15 | CA33: =CA32+F60 -> -991.24599 | CC33: 总 | CE33: 333.15 | CI33: =CI32+F60 -> -993.01289 | CK33: 总 | CM33: 333.15 | CP33: =CP32+F60 -> -987.30644 | CT33: 333.15 | CW33: =CW32+F60 -> -988.17398 | CY33: 总 | DA33: 333.15 | DD33: =DD32+F52 -> -877.786
A34: C6H12O+(H2O)* | I34: C6H12O+(H2O)* | Q34: C6H12O+(H2O)* | X34: C6H12O+(H2O)* | AF34: C6H12O+(H2O)* | AM34: C6H12O+(H2O)* | AT34: C6H12O+(H2O)* | BA34: C6H12O+(H2O)* | BH34: C6H12O+(H2O)* | BO34: C6H12O+(H2O)* | BV34: C6H12O+(H2O)* | CC34: C6H12O+(H2O)* | CK34: C6H12O+(H2O)* | CR34: C6H12O+(H2O)* | CY34: C6H12O+(H2O)*
B35: E0 | C35: T | D35: 地址 | E35: ΔG | F35: G | J35: E0 | K35: T | L35: 地址 | M35: ΔG | N35: G | R35: E0 | S35: T | T35: 地址 | U35: ΔG | V35: G | Y35: E0 | Z35: T | AA35: 地址 | AB35: ΔG | AC35: G | AG35: E0 | AH35: T | AI35: 地址 | AJ35: ΔG | AK35: G | AN35: E0 | AO35: T | AP35: 地址 | AQ35: ΔG | AR35: G | AU35: E0 | AV35: T | AW35: 地址 | AX35: ΔG | AY35: G | BB35: E0 | BC35: T | BD35: 地址 | BE35: ΔG | BF35: G | BI35: E0 | BJ35: T | BK35: 地址 | BL35: ΔG | BM35: G | BP35: E0 | BQ35: T | BR35: 地址 | BS35: ΔG | BT35: G | BW35: E0 | BX35: T | BY35: 地址 | BZ35: ΔG | CA35: G | CD35: E0 | CE35: T | CG35: 地址 | CH35: ΔG | CI35: G | CL35: E0 | CM35: T | CN35: 地址 | CO35: ΔG | CP35: G | CS35: E0 | CT35: T | CU35: 地址 | CV35: ΔG | CW35: G | CZ35: E0 | DA35: T | DB35: 地址 | DC35: ΔG | DD35: G
A36: 9 | B36: -885.76454 | D36: /home/liyaqian/node01data/ts-1/mfi/si66o98h68/1-hex+ooh+h/6h2o-ts/chu/h2o | E36: =1.455101/2 -> 0.7275505 | F36: =B36+E36 -> -885.03699 | I36: 9 | J36: -886.8953 | L36: /home/zhengxiuhui/node03data/lyq/ts-1/timn/h2o | M36: =1.447299/2 -> 0.7236495 | N36: =J36+M36 -> -886.17165 | Q36: 9 | R36: -893.44572 | T36: /home/liyaqian/node01data/ts-1/mfi/tihf/6h+oh/h2o | U36: =1.37441/2 -> 0.687205 | V36: =R36+U36 -> -892.75852 | X36: 9 | Y36: -888.45349 | AA36: /home/xiuhui/lyq/ts-1/tire/6oh+h/h2o | AB36: =1.420601/2 -> 0.7103005 | AC36: =Y36+AB36 -> -887.74319 | AF36: 9 | AG36: -891.14119 | AI36: /home/liyaqian/node01data/ts-1/mfi/tinb/catmap/h2o | AJ36: =1.365199/2 -> 0.6825995 | AK36: =AG36+AJ36 -> -890.45859 | AM36: 9 | AN36: -889.05863 | AP36: /home/zhengxiuhui/node03data/lyq/ts-1/timo/6o+oh/h2o | AQ36: =1.42928/2 -> 0.71464 | AR36: =AN36+AQ36 -> -888.34399 | AU36: -889.80181 | AW36: /home/xiuhui/lyq/ts-1/tiv/6o+oh/h2o | AX36: =1.482316/2 -> 0.741158 | AY36: =AU36+AX36 -> -889.06065 | BB36: -891.68189 | BD36: /home/liyaqian/node01data/ts-1/mfi/tizr/6o+oh/h2o | BE36: =1.415553/2 -> 0.7077765 | BF36: =BB36+BE36 -> -890.97412 | BI36: -882.38745 | BK36: /home/xiuhui/lyq/ts-1/tico/h2o | BL36: =1.436994/2 -> 0.718497 | BM36: =BI36+BL36 -> -881.66895 | BO36: 9 | BP36: -889.81816 | BR36: /home/xiuhui/lyq/ts-1/titi/6oh+h/h2o | BS36: =1.594303/2 -> 0.7971515 | BT36: =BP36+BS36 -> -889.02101 | BV36: 9 | BW36: -891.41002 | BY36: /home/liyaqian/node01data/ts-1/mfi/tiw/catmap/h2o | BZ36: =1.405446/2 -> 0.702723 | CA36: =BW36+BZ36 -> -890.7073 | CD36: -892.94577 | CG36: /home/liyaqian/node01data/ts-1/mfi/tita/catmap/h2o | CH36: =1.417509/2 -> 0.7087545 | CI36: =CH36+CD36 -> -892.23702 | CL36: -887.44267 | CN36: /home/xiuhui/lyq/ts-1/ticr/3/chu/h2o | CO36: 0.766731 | CP36: -886.67594 | CR36: 6 | CS36: -888.39687 | CU36: /home/liyaqian/node01data/ts-1/mfi/ti/6/h2o | CV36: =1.500372/2 -> 0.750186 | CW36: =CS36+CV36 -> -887.64668 | CZ36: -988.05929 | DB36: /home/liyaqian/node01data/ts-1/mfi/tini/ooh-c6h12 | DC36: =9.380488/2 -> 4.690244 | DD36: =CZ36+DC36 -> -983.36904
A37: 总 | F37: =F36+F60 -> -986.07476 | I37: 总 | N37: =N36+F60 -> -987.20942 | Q37: 总 | X37: 总 | AF37: 总 | AM37: 总 | BO37: 总 | BV37: 总 | CR37: 总
A39: C6H12O+H2O | I39: C6H12O+H2O | Q39: C6H12O+H2O | X39: C6H12O+H2O | AF39: C6H12O+H2O | AM39: C6H12O+H2O | AT39: C6H12O+H2O | BA39: C6H12O+H2O | BH39: C6H12O+H2O | BO39: C6H12O+H2O | BV39: C6H12O+H2O | CC39: C6H12O+H2O | CK39: C6H12O+H2O | CR39: C6H12O+H2O | CY39: C6H12O+H2O
B40: E0 | C40: T | D40: 地址 | E40: ΔG | F40: G | J40: E0 | K40: T | L40: 地址 | M40: ΔG | N40: G | R40: E0 | S40: T | T40: 地址 | U40: ΔG | V40: G | Y40: E0 | Z40: T | AA40: 地址 | AB40: ΔG | AC40: G | AG40: E0 | AH40: T | AI40: 地址 | AJ40: ΔG | AK40: G | AN40: E0 | AO40: T | AP40: 地址 | AQ40: ΔG | AR40: G | AU40: E0 | AV40: T | AW40: 地址 | AX40: ΔG | AY40: G | BB40: E0 | BC40: T | BD40: 地址 | BE40: ΔG | BF40: G | BI40: E0 | BJ40: T | BK40: 地址 | BL40: ΔG | BM40: G | BP40: E0 | BQ40: T | BR40: 地址 | BS40: ΔG | BT40: G | BW40: E0 | BX40: T | BY40: 地址 | BZ40: ΔG | CA40: G | CD40: E0 | CE40: T | CG40: 地址 | CH40: ΔG | CI40: G | CL40: E0 | CM40: T | CN40: 地址 | CO40: ΔG | CP40: G | CS40: E0 | CT40: T | CU40: 地址 | CV40: ΔG | CW40: G | CZ40: E0 | DA40: T | DB40: 地址 | DC40: ΔG | DD40: G
A41: 10 | B41: -871.12836 | C41: 333.15 | D41: /home/liyaqian/node01data/ts-1/mfi/si66o98h68/1-hex+ooh+h/7final_2/freq | E41: 0.167806 | F41: =B41+E41 -> -870.96055 | I41: 10 | J41: -872.09404 | K41: 333.15 | L41: /home/zhengxiuhui/node02data/lyq/ts-1/timn/7/freq | M41: 0.176445 | N41: =J41+M41 -> -871.91759 | Q41: 10 | R41: -878.57394 | S41: 333.15 | T41: /home/liyaqian/node01data/ts-1/mfi/tihf/7/freq | U41: 0.135623 | V41: =R41+U41 -> -878.43831 | X41: 10 | Y41: -873.49612 | Z41: 333.15 | AA41: /home/xiuhui/lyq/ts-1/tire/7/freq | AB41: 0.114622 | AC41: =Y41+AB41 -> -873.38149 | AF41: 10 | AG41: -876.10026 | AH41: 333.15 | AI41: /home/liyaqian/node01data/ts-1/mfi/tinb/7/freq | AJ41: 0.155407 | AK41: =AG41+AJ41 -> -875.94485 | AM41: 10 | AN41: -873.99495 | AO41: 333.15 | AP41: /home/zhengxiuhui/node03data/lyq/ts-1/timo/7/freq | AQ41: 0.134259 | AR41: =AN41+AQ41 -> -873.86069 | AT41: 7 | AU41: -875.08093 | AV41: 333.15 | AW41: /home/xiuhui/lyq/ts-1/tiv/7/freq | AX41: 0.180592 | AY41: =AU41+AX41 -> -874.90034 | BA41: 7 | BB41: -876.8073 | BC41: 333.15 | BD41: /home/liyaqian/node01data/ts-1/mfi/tizr/7/freq | BE41: 0.159183 | BF41: =BB41+BE41 -> -876.64812 | BH41: 7 | BI41: -867.78158 | BJ41: 333.15 | BK41: /home/zhengxiuhui/node02data/lyq/ts-1/tico/7/freq | BL41: 0.142565 | BM41: =BI41+BL41 -> -867.63901 | BO41: 7 | BP41: -874.85681 | BQ41: 333.15 | BR41: /home/xiuhui/lyq/ts-1/titi/7/freq | BS41: 0.226095 | BT41: =BP41+BS41 -> -874.63072 | BV41: 10 | BW41: -876.36239 | BX41: 333.15 | BY41: /home/zhengxiuhui/node02data/lyq/ts-1/tiw/7/freq | BZ41: 0.122408 | CA41: =BW41+BZ41 -> -876.23998 | CC41: 7 | CD41: -877.83182 | CE41: 333.15 | CG41: /home/zhengxiuhui/node03data/lyq/ts-1/tita/7/freq | CH41: 0.128647 | CI41: =CD41+CH41 -> -877.70318 | CK41: 7 | CL41: -872.48794 | CM41: 333.15 | CN41: /home/zhengxiuhui/node02data/lyq/ts-1/ticr/7/freq | CO41: 0.214101 | CP41: =CL41+CO41 -> -872.27384 | CR41: 7 | CS41: -873.86194 | CT41: 333.15 | CU41: /home/liyaqian/node01data/ts-1/mfi/ti/7/freq | CV41: 0.231075 | CW41: =CS41+CV41 -> -873.63087 | CY41: 7 | CZ41: -863.31769 | DA41: 333.15 | DB41: /home/zhengxiuhui/node03data/lyq/ts-1/tini/7/freq | DC41: 0.180348 | DD41: =CZ41+DC41 -> -863.13735
...

Sheet catmap数据集
B1: TiFe | J1: TiMn | R1: TiHf | Y1: TiRe | AG1: TiNb | AN1: TiMo | AU1: TiV | BB1: TiZr | BI1: TiCo | BP1: TiTi | BW1: TiW | CD1: TiTa | CL1: TiCr | CS1: 单核Ti | CZ1: TiNi
B2: H2O2_111 | J2: H2O2_111 | R2: H2O2_111 | Y2: H2O2_111 | AG2: H2O2_111 | AN2: H2O2_111 | AU2: H2O2_111 | BB2: H2O2_111 | BI2: H2O2_111 | BP2: H2O2_111 | BW2: H2O2_111 | CD2: H2O2_111 | CL2: H2O2_111 | CS2: H2O2_111 | CZ2: H2O2_111
C3: E0 | D3: T | E3: 地址 | F3: ΔG | G3: G | K3: E0 | L3: T | M3: 地址 | N3: ΔG | O3: G | S3: E0 | T3: T | U3: 地址 | V3: ΔG | W3: G | Z3: E0 | AA3: T | AB3: 地址 | AC3: ΔG | AD3: G | AH3: E0 | AI3: T | AJ3: 地址 | AK3: ΔG | AL3: G | AO3: E0 | AP3: T | AQ3: 地址 | AR3: ΔG | AS3: G | AV3: E0 | AW3: T | AX3: 地址 | AY3: ΔG | AZ3: G | BC3: E0 | BD3: T | BE3: 地址 | BF3: ΔG | BG3: G | BJ3: E0 | BK3: T | BL3: 地址 | BM3: ΔG | BN3: G | BQ3: E0 | BR3: T | BS3: 地址 | BT3: ΔG | BU3: G | BX3: E0 | BY3: T | BZ3: 地址 | CA3: ΔG | CB3: G | CE3: E0 | CF3: T | CG3: 地址 | CH3: ΔG | CI3: G | CM3: E0 | CN3: T | CO3: 地址 | CP3: ΔG | CQ3: G | CT3: E0 | CU3: T | CV3: 地址 | CW3: ΔG | CX3: G | DA3: E0 | DB3: T | DC3: 地址 | DD3: ΔG | DE3: G
B4: 1 | C4: -888.86368 | E4: /home/liyaqian/node01data/ts-1/mfi/si66o98h68/test5/tife/tiofe-t/h2o2 | F4: =1.616956 /2 -> 0.808478 | G4: =C4+F4 -> -888.0552 | J4: 1 | K4: -890.84805 | M4: /home/zhengxiuhui/node03data/lyq/ts-1/timn/h2o2 | N4: =1.599896/2 -> 0.799948 | O4: =K4+N4 -> -890.0481 | R4: 1 | S4: -897.38285 | U4: /home/liyaqian/node01data/ts-1/mfi/tihf/2h+oh/h2o2 | V4: =1.488115/2 -> 0.7440575 | W4: =S4+V4 -> -896.63879 | Y4: 1 | Z4: -892.37875 | AB4: /home/xiuhui/lyq/ts-1/tire/2o+ooh/h2o2 | AC4: =1.516751/2 -> 0.7583755 | AD4: =Z4+AC4 -> -891.62037 | AG4: 1 | AH4: -895.11216 | AJ4: /home/liyaqian/node01data/ts-1/mfi/tinb/catmap/h2o2 | AK4: =1.573585/2 -> 0.7867925 | AL4: =AH4+AK4 -> -894.32537 | AN4: 1 | AO4: -893.01495 | AQ4: /home/zhengxiuhui/node03data/lyq/ts-1/timo/2h+ooh/h2o2 | AR4: =1.460186/2 -> 0.730093 | AS4: =AO4+AR4 -> -892.28486 | AU4: 1 | AV4: -893.78058 | AX4: /home/xiuhui/lyq/ts-1/tiv/h2o2 | AY4: =1.589049/2 -> 0.7945245 | AZ4: =AV4+AY4 -> -892.98605 | BB4: 1 | BC4: -895.62208 | BE4: /home/liyaqian/node01data/ts-1/mfi/tizr/2o+ooh/h2o2 | BF4: =1.54176/2 -> 0.77088 | BG4: =BC4+BF4 -> -894.8512 | BI4: 1 | BJ4: -886.41001 | BL4: /home/xiuhui/lyq/ts-1/tico/h2o2 | BM4: =1.432429 /2 -> 0.7162145 | BN4: =BJ4+BM4 -> -885.69379 | BP4: 1 | BQ4: -893.04955 | BS4: /home/xiuhui/lyq/ts-1/titi/2ooh+h/h2o2 | BT4: =1.774977/2 -> 0.8874885 | BU4: =BQ4+BT4 -> -892.16206 | BW4: 1 | BX4: -895.33408 | BZ4: /home/liyaqian/node01data/ts-1/mfi/tiw/catmap/h2o2 | CA4: =1.578092/2 -> 0.789046 | CB4: =BX4+CA4 -> -894.54504 | CD4: 1 | CE4: -896.89764 | CG4: /home/liyaqian/node01data/ts-1/mfi/tita/catmap/h2o2 | CH4: =1.46196/2 -> 0.73098 | CI4: =CE4+CH4 -> -896.16666 | CL4: 1 | CM4: -891.36858 | CO4: /home/xiuhui/lyq/ts-1/ticr/2ooh+h/h2o2 | CP4: =1.695026/2 -> 0.847513 | CQ4: =CM4+CP4 -> -890.52107 | CS4: 1 | CT4: -892.38558 | CV4: /home/liyaqian/node01data/ts-1/mfi/ti/2ooh+h/h2o2 | CW4: =1.549208/2 -> 0.774604 | CX4: =CT4+CW4 -> -891.61098 | CZ4: 1 | DA4: -882.51939 | DC4: /home/liyaqian/node01data/ts-1/mfi/tini/2ooh+h/h2o2 | DD4: =1.67722/2 -> 0.83861 | DE4: =DA4+DD4 -> -881.68078
B5: 总 | J5: 总 | R5: 总 | Y5: 总 | AG5: 总 | AN5: 总 | AU5: 总 | BB5: 总 | BI5: 总 | BP5: 总 | BW5: 总 | CD5: 总 | CL5: 总 | CS5: 总 | CZ5: 总
B6: H_a_111 | J6: H_a_111 | R6: H_a_111 | Y6: H_a_111 | AG6: H_a_111 | AN6: H_a_111 | AU6: H_a_111 | BB6: H_a_111 | BI6: H_a_111 | BP6: H_a_111 | BW6: H_a_111 | CD6: H_a_111 | CL6: H_a_111 | CS6: H_a_111 | CZ6: H_a_111
C7: E0 | D7: T | E7: 地址 | F7: ΔG | G7: G | K7: E0 | L7: T | M7: 地址 | N7: ΔG | O7: G | S7: E0 | T7: T | U7: 地址 | V7: ΔG | W7: G | Z7: E0 | AA7: T | AB7: 地址 | AC7: ΔG | AD7: G | AH7: E0 | AI7: T | AJ7: 地址 | AK7: ΔG | AL7: G | AO7: E0 | AP7: T | AQ7: 地址 | AR7: ΔG | AS7: G | AV7: E0 | AW7: T | AX7: 地址 | AY7: ΔG | AZ7: G | BC7: E0 | BD7: T | BE7: 地址 | BF7: ΔG | BG7: G | BJ7: E0 | BK7: T | BL7: 地址 | BM7: ΔG | BN7: G | BQ7: E0 | BR7: T | BS7: 地址 | BT7: ΔG | BU7: G | BX7: E0 | BY7: T | BZ7: 地址 | CA7: ΔG | CB7: G | CE7: E0 | CF7: T | CG7: 地址 | CH7: ΔG | CI7: G | CM7: E0 | CN7: T | CO7: 地址 | CP7: ΔG | CQ7: G | CT7: E0 | CU7: T | CV7: 地址 | CW7: ΔG | CX7: G | DA7: E0 | DB7: T | DC7: 地址 | DD7: ΔG | DE7: G
B8: 2 | C8: -874.37969 | E8: /home/liyaqian/node01data/ts-1/mfi/si66o98h68/test5/tife/tiofe-t/h_a | F8: =0.828265/2 -> 0.4141325 | G8: =C8+F8 -> -873.96556 | J8: 2 | K8: -875.67782 | M8: /home/zhengxiuhui/node03data/lyq/ts-1/timn/h_a | N8: =0.885699/2 -> 0.4428495 | O8: =K8+N8 -> -875.23497 | R8: 2 | S8: -880.7957 | U8: /home/liyaqian/node01data/ts-1/mfi/tihf/6h+oh/h_a | V8: =0.713265/2 -> 0.3566325 | W8: =S8+V8 -> -880.43907 | Y8: 2 | Z8: -876.4316 | AB8: /home/xiuhui/lyq/ts-1/tire/2o+ooh/h_a | AC8: =0.754503/2 -> 0.3772515 | AD8: =Z8+AC8 -> -876.05435 | AG8: 2 | AH8: -878.85652 | AJ8: /home/liyaqian/node01data/ts-1/mfi/tinb/catmap/h_a | AK8: =0.757342 /2 -> 0.378671 | AL8: =AH8+AK8 -> -878.47785 | AN8: 2 | AO8: -877.17363 | AQ8: /home/zhengxiuhui/node03data/lyq/ts-1/timo/2h+ooh/h_a | AR8: =0.778738/2 -> 0.389369 | AS8: =AO8+AR8 -> -876.78426 | AU8: 2 | AV8: -877.65209 | AX8: /home/xiuhui/lyq/ts-1/tiv/2h+ooh/h_a | AY8: =0.846345/2 -> 0.4231725 | AZ8: =AV8+AY8 -> -877.22891 | BB8: 2 | BC8: -879.10935 | BE8: /home/liyaqian/node01data/ts-1/mfi/tizr/2o+ooh/h_a | BF8: =0.710692/2 -> 0.355346 | BG8: =BC8+BF8 -> -878.75401 | BI8: 2 | BJ8: -872.16146 | BL8: /home/xiuhui/lyq/ts-1/tico/h_a | BM8: =0.827573/2 -> 0.4137865 | BN8: =BJ8+BM8 -> -871.74767 | BP8: 2 | BQ8: -877.18867 | BS8: /home/xiuhui/lyq/ts-1/titi/2ooh+h/h | BT8: =0.919696/2 -> 0.459848 | BU8: =BQ8+BT8 -> -876.72882 | BW8: 2 | BX8: -878.92636 | BZ8: /home/liyaqian/node01data/ts-1/mfi/tiw/catmap/h_a | CA8: =0.767791/2 -> 0.3838955 | CB8: =BX8+CA8 -> -878.54247 | CD8: 2 | CE8: -880.62558 | CG8: /home/liyaqian/node01data/ts-1/mfi/tita/catmap/h_a | CH8: =0.699088/2 -> 0.349544 | CI8: =CE8+CH8 -> -880.27604 | CL8: 2 | CM8: -875.80131 | CO8: /home/xiuhui/lyq/ts-1/ticr/2ooh+h/h_a | CP8: =0.903535/2 -> 0.4517675 | CQ8: =CM8+CP8 -> -875.34954 | CS8: 2 | CT8: -874.76657 | CV8: /home/liyaqian/node01data/ts-1/mfi/ti/2ooh+h/h_a | CW8: =0.914686/2 -> 0.457343 | CX8: =CT8+CW8 -> -874.30923 | CZ8: 2 | DA8: -868.52151 | DC8: /home/liyaqian/node01data/ts-1/mfi/tini/2ooh+h/h_a | DD8: =0.903302/2 -> 0.451651 | DE8: =DA8+DD8 -> -868.06986
B9: 总 | J9: 总 | R9: 总 | Y9: 总 | AG9: 总 | AN9: 总 | AU9: 总 | BB9: 总 | BI9: 总 | BP9: 总 | BW9: 总 | CD9: 总 | CL9: 总 | CS9: 总 | CZ9: 总
B10: H_b_111 | J10: H_b_111 | R10: H_b_111 | Y10: H_b_111 | AG10: H_b_111 | AN10: H_b_111 | AU10: H_b_111 | BB10: H_b_111 | BI10: H_b_111 | BP10: H_b_111 | BW10: H_b_111 | CD10: H_b_111 | CL10: H_b_111 | CS10: H_b_111 | CZ10: H_b_111
C11: E0 | D11: T | E11: 地址 | F11: ΔG | G11: G | K11: E0 | L11: T | M11: 地址 | N11: ΔG | O11: G | S11: E0 | T11: T | U11: 地址 | V11: ΔG | W11: G | Z11: E0 | AA11: T | AB11: 地址 | AC11: ΔG | AD11: G | AH11: E0 | AI11: T | AJ11: 地址 | AK11: ΔG | AL11: G | AO11: E0 | AP11: T | AQ11: 地址 | AR11: ΔG | AS11: G | AV11: E0 | AW11: T | AX11: 地址 | AY11: ΔG | AZ11: G | BC11: E0 | BD11: T | BE11: 地址 | BF11: ΔG | BG11: G | BJ11: E0 | BK11: T | BL11: 地址 | BM11: ΔG | BN11: G | BQ11: E0 | BR11: T | BS11: 地址 | BT11: ΔG | BU11: G | BX11: E0 | BY11: T | BZ11: 地址 | CA11: ΔG | CB11: G | CE11: E0 | CF11: T | CG11: 地址 | CH11: ΔG | CI11: G | CM11: E0 | CN11: T | CO11: 地址 | CP11: ΔG | CQ11: G | CT11: E0 | CU11: T | CV11: 地址 | CW11: ΔG | CX11: G | DA11: E0 | DB11: T | DC11: 地址 | DD11: ΔG | DE11: G
B12: 3 | C12: -875.44337 | E12: /home/liyaqian/node01data/ts-1/mfi/si66o98h68/1-hex+ooh+h/6h2o-ts/chu/h_b | F12: =0.850012/2 -> 0.425006 | G12: =C12+F12 -> -875.01836 | J12: 3 | K12: -875.72943 | M12: /home/zhengxiuhui/node03data/lyq/ts-1/timn/h_b | N12: =0.87984/2 -> 0.43992 | O12: =K12+N12 -> -875.28951 | R12: 3 | S12: -879.42777 | U12: /home/liyaqian/node01data/ts-1/mfi/tihf/6h+oh/h_b | V12: =0.725121/2 -> 0.3625605 | W12: =S12+V12 -> -879.06521 | Y12: 3 | Z12: -875.75013 | AB12: /home/xiuhui/lyq/ts-1/tire/h2o/chu/h_b | AC12: =0.752047/2 -> 0.3760235 | AD12: =Z12+AC12 -> -875.37411 | AG12: 3 | AH12: -877.56892 | AJ12: /home/liyaqian/node01data/ts-1/mfi/tinb/catmap/h_b | AK12: =0.794561/2 -> 0.3972805 | AL12: =AH12+AK12 -> -877.17164 | AN12: 3 | AO12: -876.60887 | AQ12: /home/zhengxiuhui/node03data/lyq/ts-1/timo/2h+ooh/h_b | AR12: =0.791929/2 -> 0.3959645 | AS12: =AO12+AR12 -> -876.2129 | AU12: 3 | AV12: -877.29431 | AX12: /home/xiuhui/lyq/ts-1/tiv/h2o/chu/h_b | AY12: =0.950662/2 -> 0.475331 | AZ12: =AV12+AY12 -> -876.81898 | BB12: 3 | BC12: -877.85983 | BE12: /home/liyaqian/node01data/ts-1/mfi/tizr/h2o/chu/h_b | BF12: =0.783378/2 -> 0.391689 | BG12: =BC12+BF12 -> -877.46814 | BI12: 3 | BJ12: -872.16253 | BL12: /home/xiuhui/lyq/ts-1/tico/h_b | BM12: =0.748387/2 -> 0.3741935 | BN12: =BJ12+BM12 -> -871.78834 | BP12: 3 | BQ12: -876.91868 | BS12: /home/xiuhui/lyq/ts-1/titi/h2o/chu/h_b | BT12: =0.871308/2 -> 0.435654 | BU12: =BQ12+BT12 -> -876.48302 | BW12: 3 | BX12: -877.66814 | BZ12: /home/liyaqian/node01data/ts-1/mfi/tiw/catmap/h_b | CA12: =0.195549/2 -> 0.0977745 | CB12: =BX12+CA12 -> -877.57036 | CD12: 3 | CE12: -879.1806 | CG12: /home/liyaqian/node01data/ts-1/mfi/tita/catmap/h_b | CH12: =0.741139/2 -> 0.3705695 | CI12: =CE12+CH12 -> -878.81003 | CL12: 3 | CM12: -875.14353 | CO12: /home/liyaqian/node01data/ts-1/mfi/ticr/catmap/h_b | CP12: =0.941579/2 -> 0.4707895 | CQ12: =CM12+CP12 -> -874.67274 | CS12: 3 | CT12: -879.75575 | CV12: /home/liyaqian/node01data/ts-1/mfi/ti/h2o/chu2/h_b | CW12: =1.080119/2 -> 0.5400595 | CX12: =CT12+CW12 -> -879.21569 | CZ12: 3 | DA12: -868.36107 | DC12: /home/liyaqian/node01data/ts-1/mfi/tini/3/chu/h_b | DD12: =0.89763/2 -> 0.448815 | DE12: =DA12+DD12 -> -867.91225
B13: 总 | J13: 总 | R13: 总 | Y13: 总 | AG13: 总 | AN13: 总 | AU13: 总 | BB13: 总 | BI13: 总 | BP13: 总 | BW13: 总 | CD13: 总 | CL13: 总 | CS13: 总 | CZ13: 总
B14: OOH_111 | J14: OOH_111 | R14: OOH_111 | Y14: OOH_111 | AG14: OOH_111 | AN14: OOH_111 | AU14: OOH_111 | BB14: OOH_111 | BI14: OOH_111 | BP14: OOH_111 | BW14: OOH_111 | CD14: OOH_111 | CL14: OOH_111 | CS14: OOH_111 | CZ14: OOH_111
B15: eV | C15: E0 | D15: T | E15: 地址 | F15: ΔG | G15: G | J15: eV | K15: E0 | L15: T | M15: 地址 | N15: ΔG | O15: G | R15: eV | S15: E0 | T15: T | U15: 地址 | V15: ΔG | W15: G | Y15: eV | Z15: E0 | AA15: T | AB15: 地址 | AC15: ΔG | AD15: G | AG15: eV | AH15: E0 | AI15: T | AJ15: 地址 | AK15: ΔG | AL15: G | AN15: eV | AO15: E0 | AP15: T | AQ15: 地址 | AR15: ΔG | AS15: G | AU15: eV | AV15: E0 | AW15: T | AX15: 地址 | AY15: ΔG | AZ15: G | BB15: eV | BC15: E0 | BD15: T | BE15: 地址 | BF15: ΔG | BG15: G | BI15: eV | BJ15: E0 | BK15: T | BL15: 地址 | BM15: ΔG | BN15: G | BP15: eV | BQ15: E0 | BR15: T | BS15: 地址 | BT15: ΔG | BU15: G | BW15: eV | BX15: E0 | BY15: T | BZ15: 地址 | CA15: ΔG | CB15: G | CD15: eV | CE15: E0 | CF15: T | CG15: 地址 | CH15: ΔG | CI15: G | CL15: eV | CM15: E0 | CN15: T | CO15: 地址 | CP15: ΔG | CQ15: G | CS15: eV | CT15: E0 | CU15: T | CV15: 地址 | CW15: ΔG | CX15: G | CZ15: eV | DA15: E0 | DB15: T | DC15: 地址 | DD15: ΔG | DE15: G
B16: 4 | C16: -884.19389 | E16: /home/liyaqian/node01data/ts-1/mfi/si66o98h68/test5/tife/tiofe-t/ooh | F16: =1.177308/2 -> 0.588654 | G16: =C16+F16 -> -883.60523 | J16: 4 | K16: -886.48389 | M16: /home/zhengxiuhui/node03data/lyq/ts-1/timn/ooh | N16: =1.223922/2 -> 0.611961 | O16: =K16+N16 -> -885.87193 | R16: 4 | S16: -892.50416 | U16: /home/liyaqian/node01data/ts-1/mfi/tihf/2h+oh/ooh | V16: =0.818313/2 -> 0.4091565 | W16: =S16+V16 -> -892.095 | Y16: 4 | Z16: -888.82943 | AB16: /home/xiuhui/lyq/ts-1/tire/2o+ooh/ooh | AC16: =0.978727/2 -> 0.4893635 | AD16: =Z16+AC16 -> -888.34007 | AG16: 4 | AH16: -892.28673 | AJ16: /home/liyaqian/node01data/ts-1/mfi/tinb/catmap/ooh | AK16: =1.151279/2 -> 0.5756395 | AL16: =AH16+AK16 -> -891.71109 | AN16: 4 | AO16: -889.73794 | AQ16: /home/zhengxiuhui/node03data/lyq/ts-1/timo/2h+ooh/ooh | AR16: 1.046068 | AS16: =AO16+AR16 -> -888.69188 | AU16: 4 | AV16: -890.09228 | AX16: /home/xiuhui/lyq/ts-1/tiv/2h+ooh/ooh | AY16: =1.197531/2 -> 0.5987655 | AZ16: =AV16+AY16 -> -889.49351 | BB16: 4 | BC16: -890.74811 | BE16: /home/liyaqian/node01data/ts-1/mfi/tizr/2o+ooh/ooh | BF16: =0.875168/2 -> 0.437584 | BG16: =BC16+BF16 -> -890.31053 | BI16: 4 | BJ16: -881.63357 | BL16: /home/xiuhui/lyq/ts-1/tico/ooh | BM16: =0.987835/2 -> 0.4939175 | BN16: =BJ16+BM16 -> -881.13965 | BP16: 4 | BQ16: -888.24982 | BS16: /home/xiuhui/lyq/ts-1/titi/2ooh+h/ooh | BT16: =1.121408/2 -> 0.560704 | BU16: =BQ16+BT16 -> -887.68911 | BW16: 4 | BX16: -891.8993 | BZ16: /home/liyaqian/node01data/ts-1/mfi/tiw/catmap/ooh | CA16: =1.040508/2 -> 0.520254 | CB16: =BX16+CA16 -> -891.37904 | CD16: 4 | CE16: -894.27847 | CG16: /home/liyaqian/node01data/ts-1/mfi/tita/catmap/ooh | CH16: =1.105577/2 -> 0.5527885 | CI16: =CE16+CH16 -> -893.72568 | CL16: 4 | CM16: -887.34098 | CO16: /home/liyaqian/node01data/ts-1/mfi/ticr/catmap/ooh | CP16: =1.215072/2 -> 0.607536 | CQ16: =CM16+CP16 -> -886.73344 | CS16: 4 | CT16: -887.52279 | CV16: /home/liyaqian/node01data/ts-1/mfi/ti/2ooh+h/ooh | CW16: =1.01116/2 -> 0.50558 | CX16: =CT16+CW16 -> -887.01721 | CZ16: 4 | DA16: -877.71477 | DC16: /home/liyaqian/node01data/ts-1/mfi/tini/2ooh+h/ooh | DD16: =1.142745/2 -> 0.5713725 | DE16: =DD16+DA16 -> -877.14339
B17: 总 | J17: 总 | R17: 总 | Y17: 总 | AG17: 总 | AN17: 总 | AU17: 总 | BB17: 总 | BI17: 总 | BP17: 总 | BW17: 总 | CD17: 总 | CL17: 总 | CS17: 总 | CZ17: 总
B18: C6H12_111 | J18: C6H12_111 | R18: C6H12_111 | Y18: C6H12_111 | AG18: C6H12_111 | AN18: C6H12_111 | AU18: C6H12_111 | BB18: C6H12_111 | BI18: C6H12_111 | BP18: C6H12_111 | BW18: C6H12_111 | CD18: C6H12_111 | CL18: C6H12_111 | CS18: C6H12_111 | CZ18: C6H12_111
C19: E0 | D19: T | E19: 地址 | F19: ΔG | G19: G | K19: E0 | L19: T | M19: 地址 | N19: ΔG | O19: G | S19: E0 | T19: T | U19: 地址 | V19: ΔG | W19: G | Z19: E0 | AA19: T | AB19: 地址 | AC19: ΔG | AD19: G | AH19: E0 | AI19: T | AJ19: 地址 | AK19: ΔG | AL19: G | AO19: E0 | AP19: T | AQ19: 地址 | AR19: ΔG | AS19: G | AV19: E0 | AW19: T | AX19: 地址 | AY19: ΔG | AZ19: G | BC19: E0 | BD19: T | BE19: 地址 | BF19: ΔG | BG19: G | BJ19: E0 | BK19: T | BL19: 地址 | BM19: ΔG | BN19: G | BQ19: E0 | BR19: T | BS19: 地址 | BT19: ΔG | BU19: G | BX19: E0 | BY19: T | BZ19: 地址 | CA19: ΔG | CB19: G | CE19: E0 | CF19: T | CG19: 地址 | CH19: ΔG | CI19: G | CM19: E0 | CN19: T | CO19: 地址 | CP19: ΔG | CQ19: G | CT19: E0 | CU19: T | CV19: 地址 | CW19: ΔG | CX19: G | DA19: E0 | DB19: T | DC19: 地址 | DD19: ΔG | DE19: G
B20: 5 | C20: -970.30977 | E20: /home/liyaqian/node01data/ts-1/mfi/si66o98h68/1-hex+ooh+h/chu3/c6h12 | F20: =8.337212/2 -> 4.168606 | G20: =C20+F20 -> -966.14116 | J20: 5 | K20: -971.2541 | M20: /home/zhengxiuhui/node03data/lyq/ts-1/timn/c6h12 | N20: =8.372444/2 -> 4.186222 | O20: =K20+N20 -> -967.06788 | R20: 5 | S20: -977.75667 | U20: /home/liyaqian/node01data/ts-1/mfi/tihf/3/chu/c6h12 | V20: =8.398683/2 -> 4.1993415 | W20: =S20+V20 -> -973.55733 | Y20: 5 | Z20: -972.70049 | AB20: /home/xiuhui/lyq/ts-1/tire/3/chu/c6h12 | AC20: =8.330201/2 -> 4.1651005 | AD20: =Z20+AC20 -> -968.53539 | AG20: 5 | AH20: -962.01836 | AJ20: /home/liyaqian/node01data/ts-1/mfi/tinb/catmap/c6h12 | AK20: =8.478635/2 -> 4.2393175 | AL20: =AH20+AK20 -> -957.77904 | AN20: 5 | AO20: -973.2411 | AQ20: /home/zhengxiuhui/node03data/lyq/ts-1/timo/3/chu2/c6h12 | AR20: =8.390311 /2 -> 4.1951555 | AS20: =AO20+AR20 -> -969.04594 | AU20: 5 | AV20: -974.22738 | AX20: /home/xiuhui/lyq/ts-1/tiv/3/chu2/c6h12 | AY20: =8.388383/2 -> 4.1941915 | AZ20: =AV20+AY20 -> -970.03319 | BB20: 5 | BC20: -976.0373 | BE20: /home/liyaqian/node01data/ts-1/mfi/tizr/3/chu2/c6h12 | BF20: =8.348945/2 -> 4.1744725 | BG20: =BC20+BF20 -> -971.86283 | BI20: 5 | BJ20: -967.8853 | BL20: /home/xiuhui/lyq/ts-1/tico/c6h12 | BM20: =8.414548/2 -> 4.207274 | BN20: =BJ20+BM20 -> -963.67802 | BP20: 5 | BQ20: -973.33464 | BS20: /home/xiuhui/lyq/ts-1/titi/3/chu/c6h12 | BT20: =8.507553/2 -> 4.2537765 | BU20: =BQ20+BT20 -> -969.08086 | BW20: 5 | BX20: -975.4713 | BZ20: /home/liyaqian/node01data/ts-1/mfi/tiw/catmap/c6h12 | CA20: =0.243886/2 -> 0.121943 | CB20: =BX20+CA20 -> -975.34936 | CD20: 5 | CE20: -976.99637 | CG20: /home/liyaqian/node01data/ts-1/mfi/tita/catmap/c6h12 | CH20: =8.301055/2 -> 4.1505275 | CI20: =CE20+CH20 -> -972.84585 | CL20: 5 | CM20: -971.69677 | CO20: /home/xiuhui/lyq/ts-1/ticr/3/chu/c6h12 | CP20: =8.44664/2 -> 4.22332 | CQ20: =CM20+CP20 -> -967.47345 | CS20: 5 | CT20: -973.01413 | CV20: /home/liyaqian/node01data/ts-1/mfi/ti/3/chu/c6h12 | CW20: =8.506413/2 -> 4.2532065 | CX20: =CT20+CW20 -> -968.76093 | CZ20: 5 | DA20: -962.50679 | DC20: /home/liyaqian/node01data/ts-1/mfi/tini/3/chu/c6h12 | DD20: =8.356027/2 -> 4.1780135 | DE20: =DA20+DD20 -> -958.32878
B21: 总 | J21: 总 | R21: 总 | Y21: 总 | AG21: 总 | AN21: 总 | AU21: 总 | BB21: 总 | BI21: 总 | BP21: 总 | BW21: 总 | CD21: 总 | CL21: 总 | CS21: 总 | CZ21: 总
B22: C6H12O_111 | J22: C6H12O_111 | R22: C6H12O_111 | Y22: C6H12O_111 | AG22: C6H12O_111 | AN22: C6H12O_111 | AU22: C6H12O_111 | BB22: C6H12O_111 | BI22: C6H12O_111 | BP22: C6H12O_111 | BW22: C6H12O_111 | CD22: C6H12O_111 | CL22: C6H12O_111 | CS22: C6H12O_111 | CZ22: C6H12O_111
C23: E0 | D23: T | E23: 地址 | F23: ΔG | G23: G | K23: E0 | L23: T | M23: 地址 | N23: ΔG | O23: G | S23: E0 | T23: T | U23: 地址 | V23: ΔG | W23: G | Z23: E0 | AA23: T | AB23: 地址 | AC23: ΔG | AD23: G | AH23: E0 | AI23: T | AJ23: 地址 | AK23: ΔG | AL23: G | AO23: E0 | AP23: T | AQ23: 地址 | AR23: ΔG | AS23: G | AV23: E0 | AW23: T | AX23: 地址 | AY23: ΔG | AZ23: G | BC23: E0 | BD23: T | BE23: 地址 | BF23: ΔG | BG23: G | BJ23: E0 | BK23: T | BL23: 地址 | BM23: ΔG | BN23: G | BQ23: E0 | BR23: T | BS23: 地址 | BT23: ΔG | BU23: G | BX23: E0 | BY23: T | BZ23: 地址 | CA23: ΔG | CB23: G | CE23: E0 | CF23: T | CG23: 地址 | CH23: ΔG | CI23: G | CM23: E0 | CN23: T | CO23: 地址 | CP23: ΔG | CQ23: G | CT23: E0 | CU23: T | CV23: 地址 | CW23: ΔG | CX23: G | DA23: E0 | DB23: T | DC23: 地址 | DD23: ΔG | DE23: G
